<?xml version="1.0" ?>
<robot name="bot_urdf_hii" xmlns:xacro="http://www.ros.org/wiki/xacro">

<xacro:include filename="$(find jack_pack)/urdf/materials.xacro" />
<xacro:include filename="$(find jack_pack)/urdf/bot_urdf_hii.trans" />
<xacro:include filename="$(find bot_urdf_hii_description)/urdf/bot_urdf_hii.gazebo" />
<xacro:include filename="$(find jack_pack)/urdf/ros2_control.xacro" />
<link name="base_link">
  <inertial>
    <origin xyz="-7.829829556326353e-11 0.024365666684909387 0.1598790754817299" rpy="0 0 0"/>
    <mass value="1.1433732359085518"/>
    <inertia ixx="0.005235" iyy="0.020337" izz="0.024577" ixy="-0.0" iyz="-0.0" ixz="-0.0"/>
  </inertial>
  <visual>
    <origin xyz="0 0 0" rpy="0 0 0"/>
    <geometry>
      <mesh filename="file://$(find bot_urdf_hii_description)/meshes/base_link.stl" scale="0.001 0.001 0.001"/>
    </geometry>
    <material name="silver"/>
  </visual>
  <collision>
    <origin xyz="0 0 0" rpy="0 0 0"/>
    <geometry>
      <mesh filename="file://$(find bot_urdf_hii_description)/meshes/base_link.stl" scale="0.001 0.001 0.001"/>
    </geometry>
  </collision>
</link>

<link name="servo_small_clip_v1__6__1">
  <inertial>
    <origin xyz="2.7945336743273597e-07 0.006816401170189237 3.333151153139813e-07" rpy="0 0 0"/>
    <mass value="0.009145592822398149"/>
    <inertia ixx="1e-06" iyy="3e-06" izz="3e-06" ixy="0.0" iyz="-0.0" ixz="0.0"/>
  </inertial>
  <visual>
    <origin xyz="-0.121498 -0.074366 -0.145634" rpy="0 0 0"/>
    <geometry>
      <mesh filename="file://$(find bot_urdf_hii_description)/meshes/servo_small_clip_v1__6__1.stl" scale="0.001 0.001 0.001"/>
    </geometry>
    <material name="silver"/>
  </visual>
  <collision>
    <origin xyz="-0.121498 -0.074366 -0.145634" rpy="0 0 0"/>
    <geometry>
      <mesh filename="file://$(find bot_urdf_hii_description)/meshes/servo_small_clip_v1__6__1.stl" scale="0.001 0.001 0.001"/>
    </geometry>
  </collision>
</link>

<link name="servo_small_clip_v1__5__1">
  <inertial>
    <origin xyz="2.7945336743273597e-07 -0.00681706780037027 3.3331511534173686e-07" rpy="0 0 0"/>
    <mass value="0.009145592822398149"/>
    <inertia ixx="1e-06" iyy="3e-06" izz="3e-06" ixy="-0.0" iyz="0.0" ixz="0.0"/>
  </inertial>
  <visual>
    <origin xyz="-0.121498 0.025634 -0.145634" rpy="0 0 0"/>
    <geometry>
      <mesh filename="file://$(find bot_urdf_hii_description)/meshes/servo_small_clip_v1__5__1.stl" scale="0.001 0.001 0.001"/>
    </geometry>
    <material name="silver"/>
  </visual>
  <collision>
    <origin xyz="-0.121498 0.025634 -0.145634" rpy="0 0 0"/>
    <geometry>
      <mesh filename="file://$(find bot_urdf_hii_description)/meshes/servo_small_clip_v1__5__1.stl" scale="0.001 0.001 0.001"/>
    </geometry>
  </collision>
</link>

<link name="servo_small_clip_v1__7__1">
  <inertial>
    <origin xyz="0.0 0.006816401170189237 3.333151153139813e-07" rpy="0 0 0"/>
    <mass value="0.009145592822398149"/>
    <inertia ixx="1e-06" iyy="3e-06" izz="3e-06" ixy="0.0" iyz="-0.0" ixz="0.0"/>
  </inertial>
  <visual>
    <origin xyz="0.1215 -0.074366 -0.145634" rpy="0 0 0"/>
    <geometry>
      <mesh filename="file://$(find bot_urdf_hii_description)/meshes/servo_small_clip_v1__7__1.stl" scale="0.001 0.001 0.001"/>
    </geometry>
    <material name="silver"/>
  </visual>
  <collision>
    <origin xyz="0.1215 -0.074366 -0.145634" rpy="0 0 0"/>
    <geometry>
      <mesh filename="file://$(find bot_urdf_hii_description)/meshes/servo_small_clip_v1__7__1.stl" scale="0.001 0.001 0.001"/>
    </geometry>
  </collision>
</link>

<link name="servo_small_clip_v1__4__1">
  <inertial>
    <origin xyz="-4.163336342344337e-17 -0.006817067800370249 3.333151155360259e-07" rpy="0 0 0"/>
    <mass value="0.009145592822398149"/>
    <inertia ixx="1e-06" iyy="3e-06" izz="3e-06" ixy="0.0" iyz="0.0" ixz="0.0"/>
  </inertial>
  <visual>
    <origin xyz="0.1215 0.025634 -0.145634" rpy="0 0 0"/>
    <geometry>
      <mesh filename="file://$(find bot_urdf_hii_description)/meshes/servo_small_clip_v1__4__1.stl" scale="0.001 0.001 0.001"/>
    </geometry>
    <material name="silver"/>
  </visual>
  <collision>
    <origin xyz="0.1215 0.025634 -0.145634" rpy="0 0 0"/>
    <geometry>
      <mesh filename="file://$(find bot_urdf_hii_description)/meshes/servo_small_clip_v1__4__1.stl" scale="0.001 0.001 0.001"/>
    </geometry>
  </collision>
</link>

<link name="Servo_RDS3115_v1__5__1">
  <inertial>
    <origin xyz="0.019999999999999907 -0.011079623170873722 3.333150907225413e-07" rpy="0 0 0"/>
    <mass value="0.050997583494915726"/>
    <inertia ixx="9e-06" iyy="1e-05" izz="1.5e-05" ixy="-0.0" iyz="-0.0" ixz="0.0"/>
  </inertial>
  <visual>
    <origin xyz="0.1415 0.042634 -0.145634" rpy="0 0 0"/>
    <geometry>
      <mesh filename="file://$(find bot_urdf_hii_description)/meshes/Servo_RDS3115_v1__5__1.stl" scale="0.001 0.001 0.001"/>
    </geometry>
    <material name="silver"/>
  </visual>
  <collision>
    <origin xyz="0.1415 0.042634 -0.145634" rpy="0 0 0"/>
    <geometry>
      <mesh filename="file://$(find bot_urdf_hii_description)/meshes/Servo_RDS3115_v1__5__1.stl" scale="0.001 0.001 0.001"/>
    </geometry>
  </collision>
</link>

<link name="Servo_RDS3115_v1__4__1">
  <inertial>
    <origin xyz="-0.01999972054663264 -0.011079623170873895 3.3331509052825226e-07" rpy="0 0 0"/>
    <mass value="0.050997583494915726"/>
    <inertia ixx="9e-06" iyy="1e-05" izz="1.5e-05" ixy="-0.0" iyz="-0.0" ixz="-0.0"/>
  </inertial>
  <visual>
    <origin xyz="-0.141498 0.042634 -0.145634" rpy="0 0 0"/>
    <geometry>
      <mesh filename="file://$(find bot_urdf_hii_description)/meshes/Servo_RDS3115_v1__4__1.stl" scale="0.001 0.001 0.001"/>
    </geometry>
    <material name="silver"/>
  </visual>
  <collision>
    <origin xyz="-0.141498 0.042634 -0.145634" rpy="0 0 0"/>
    <geometry>
      <mesh filename="file://$(find bot_urdf_hii_description)/meshes/Servo_RDS3115_v1__4__1.stl" scale="0.001 0.001 0.001"/>
    </geometry>
  </collision>
</link>

<link name="Servo_RDS3115_v1__3__1">
  <inertial>
    <origin xyz="0.020000000000000018 0.011078956540692839 3.333150904727411e-07" rpy="0 0 0"/>
    <mass value="0.050997583494915726"/>
    <inertia ixx="9e-06" iyy="1e-05" izz="1.5e-05" ixy="0.0" iyz="-0.0" ixz="0.0"/>
  </inertial>
  <visual>
    <origin xyz="0.1415 -0.091366 -0.145634" rpy="0 0 0"/>
    <geometry>
      <mesh filename="file://$(find bot_urdf_hii_description)/meshes/Servo_RDS3115_v1__3__1.stl" scale="0.001 0.001 0.001"/>
    </geometry>
    <material name="silver"/>
  </visual>
  <collision>
    <origin xyz="0.1415 -0.091366 -0.145634" rpy="0 0 0"/>
    <geometry>
      <mesh filename="file://$(find bot_urdf_hii_description)/meshes/Servo_RDS3115_v1__3__1.stl" scale="0.001 0.001 0.001"/>
    </geometry>
  </collision>
</link>

<link name="Servo_RDS3115_v1__2__1">
  <inertial>
    <origin xyz="-0.01999972054663257 0.011078956540692839 3.333150904727411e-07" rpy="0 0 0"/>
    <mass value="0.050997583494915726"/>
    <inertia ixx="9e-06" iyy="1e-05" izz="1.5e-05" ixy="0.0" iyz="0.0" ixz="0.0"/>
  </inertial>
  <visual>
    <origin xyz="-0.141498 -0.091366 -0.145634" rpy="0 0 0"/>
    <geometry>
      <mesh filename="file://$(find bot_urdf_hii_description)/meshes/Servo_RDS3115_v1__2__1.stl" scale="0.001 0.001 0.001"/>
    </geometry>
    <material name="silver"/>
  </visual>
  <collision>
    <origin xyz="-0.141498 -0.091366 -0.145634" rpy="0 0 0"/>
    <geometry>
      <mesh filename="file://$(find bot_urdf_hii_description)/meshes/Servo_RDS3115_v1__2__1.stl" scale="0.001 0.001 0.001"/>
    </geometry>
  </collision>
</link>

<link name="servo_big_clip_v1__4__1">
  <inertial>
    <origin xyz="-0.0254997205466327 -5.123391884492845e-07 -0.01767339316689384" rpy="0 0 0"/>
    <mass value="0.011882867210540276"/>
    <inertia ixx="2e-06" iyy="7e-06" izz="6e-06" ixy="0.0" iyz="0.0" ixz="0.0"/>
  </inertial>
  <visual>
    <origin xyz="-0.146498 -0.111366 -0.145634" rpy="0 0 0"/>
    <geometry>
      <mesh filename="file://$(find bot_urdf_hii_description)/meshes/servo_big_clip_v1__4__1.stl" scale="0.001 0.001 0.001"/>
    </geometry>
    <material name="silver"/>
  </visual>
  <collision>
    <origin xyz="-0.146498 -0.111366 -0.145634" rpy="0 0 0"/>
    <geometry>
      <mesh filename="file://$(find bot_urdf_hii_description)/meshes/servo_big_clip_v1__4__1.stl" scale="0.001 0.001 0.001"/>
    </geometry>
  </collision>
</link>

<link name="servo_big_clip_v1__6__1">
  <inertial>
    <origin xyz="-0.025499999999999967 -5.123391891292961e-07 -0.017673393166893897" rpy="0 0 0"/>
    <mass value="0.011882867210540276"/>
    <inertia ixx="2e-06" iyy="7e-06" izz="6e-06" ixy="-0.0" iyz="0.0" ixz="-0.0"/>
  </inertial>
  <visual>
    <origin xyz="0.0965 -0.111366 -0.145634" rpy="0 0 0"/>
    <geometry>
      <mesh filename="file://$(find bot_urdf_hii_description)/meshes/servo_big_clip_v1__6__1.stl" scale="0.001 0.001 0.001"/>
    </geometry>
    <material name="silver"/>
  </visual>
  <collision>
    <origin xyz="0.0965 -0.111366 -0.145634" rpy="0 0 0"/>
    <geometry>
      <mesh filename="file://$(find bot_urdf_hii_description)/meshes/servo_big_clip_v1__6__1.stl" scale="0.001 0.001 0.001"/>
    </geometry>
  </collision>
</link>

<link name="servo_big_clip_v1__5__1">
  <inertial>
    <origin xyz="-0.025499720546632673 -5.12339188282751e-07 -0.01767339316689384" rpy="0 0 0"/>
    <mass value="0.011882867210540276"/>
    <inertia ixx="2e-06" iyy="7e-06" izz="6e-06" ixy="-0.0" iyz="0.0" ixz="0.0"/>
  </inertial>
  <visual>
    <origin xyz="-0.146498 0.062634 -0.145634" rpy="0 0 0"/>
    <geometry>
      <mesh filename="file://$(find bot_urdf_hii_description)/meshes/servo_big_clip_v1__5__1.stl" scale="0.001 0.001 0.001"/>
    </geometry>
    <material name="silver"/>
  </visual>
  <collision>
    <origin xyz="-0.146498 0.062634 -0.145634" rpy="0 0 0"/>
    <geometry>
      <mesh filename="file://$(find bot_urdf_hii_description)/meshes/servo_big_clip_v1__5__1.stl" scale="0.001 0.001 0.001"/>
    </geometry>
  </collision>
</link>

<link name="servo_big_clip_v1__3__1">
  <inertial>
    <origin xyz="-0.025500000000000134 -5.123391881023398e-07 -0.017673393166893592" rpy="0 0 0"/>
    <mass value="0.011882867210540276"/>
    <inertia ixx="2e-06" iyy="7e-06" izz="6e-06" ixy="-0.0" iyz="0.0" ixz="0.0"/>
  </inertial>
  <visual>
    <origin xyz="0.0965 0.062634 -0.145634" rpy="0 0 0"/>
    <geometry>
      <mesh filename="file://$(find bot_urdf_hii_description)/meshes/servo_big_clip_v1__3__1.stl" scale="0.001 0.001 0.001"/>
    </geometry>
    <material name="silver"/>
  </visual>
  <collision>
    <origin xyz="0.0965 0.062634 -0.145634" rpy="0 0 0"/>
    <geometry>
      <mesh filename="file://$(find bot_urdf_hii_description)/meshes/servo_big_clip_v1__3__1.stl" scale="0.001 0.001 0.001"/>
    </geometry>
  </collision>
</link>

<link name="servo_small_clip_v1__2__1">
  <inertial>
    <origin xyz="2.794533920935649e-07 -3.333150906809079e-07 -0.006816401170189279" rpy="0 0 0"/>
    <mass value="0.009145592822398149"/>
    <inertia ixx="3e-06" iyy="1e-06" izz="3e-06" ixy="0.0" iyz="0.0" ixz="0.0"/>
  </inertial>
  <visual>
    <origin xyz="-0.120998 -0.111366 -0.118634" rpy="0 0 0"/>
    <geometry>
      <mesh filename="file://$(find bot_urdf_hii_description)/meshes/servo_small_clip_v1__2__1.stl" scale="0.001 0.001 0.001"/>
    </geometry>
    <material name="silver"/>
  </visual>
  <collision>
    <origin xyz="-0.120998 -0.111366 -0.118634" rpy="0 0 0"/>
    <geometry>
      <mesh filename="file://$(find bot_urdf_hii_description)/meshes/servo_small_clip_v1__2__1.stl" scale="0.001 0.001 0.001"/>
    </geometry>
  </collision>
</link>

<link name="servo_small_clip_v1__1__1">
  <inertial>
    <origin xyz="2.4868995751603507e-14 -3.3331509130540837e-07 -0.006816401170189362" rpy="0 0 0"/>
    <mass value="0.009145592822398149"/>
    <inertia ixx="3e-06" iyy="1e-06" izz="3e-06" ixy="0.0" iyz="0.0" ixz="0.0"/>
  </inertial>
  <visual>
    <origin xyz="0.122 -0.111366 -0.118634" rpy="0 0 0"/>
    <geometry>
      <mesh filename="file://$(find bot_urdf_hii_description)/meshes/servo_small_clip_v1__1__1.stl" scale="0.001 0.001 0.001"/>
    </geometry>
    <material name="silver"/>
  </visual>
  <collision>
    <origin xyz="0.122 -0.111366 -0.118634" rpy="0 0 0"/>
    <geometry>
      <mesh filename="file://$(find bot_urdf_hii_description)/meshes/servo_small_clip_v1__1__1.stl" scale="0.001 0.001 0.001"/>
    </geometry>
  </collision>
</link>

<link name="servo_small_clip_v1_1">
  <inertial>
    <origin xyz="2.4702462297909733e-14 -3.333150902784521e-07 -0.006816401170189043" rpy="0 0 0"/>
    <mass value="0.009145592822398149"/>
    <inertia ixx="3e-06" iyy="1e-06" izz="3e-06" ixy="0.0" iyz="0.0" ixz="0.0"/>
  </inertial>
  <visual>
    <origin xyz="0.122 0.062634 -0.118634" rpy="0 0 0"/>
    <geometry>
      <mesh filename="file://$(find bot_urdf_hii_description)/meshes/servo_small_clip_v1_1.stl" scale="0.001 0.001 0.001"/>
    </geometry>
    <material name="silver"/>
  </visual>
  <collision>
    <origin xyz="0.122 0.062634 -0.118634" rpy="0 0 0"/>
    <geometry>
      <mesh filename="file://$(find bot_urdf_hii_description)/meshes/servo_small_clip_v1_1.stl" scale="0.001 0.001 0.001"/>
    </geometry>
  </collision>
</link>

<link name="servo_small_clip_v1__3__1">
  <inertial>
    <origin xyz="2.794533921074427e-07 -3.3331509052825226e-07 -0.006816401170189307" rpy="0 0 0"/>
    <mass value="0.009145592822398149"/>
    <inertia ixx="3e-06" iyy="1e-06" izz="3e-06" ixy="0.0" iyz="0.0" ixz="0.0"/>
  </inertial>
  <visual>
    <origin xyz="-0.120998 0.062634 -0.118634" rpy="0 0 0"/>
    <geometry>
      <mesh filename="file://$(find bot_urdf_hii_description)/meshes/servo_small_clip_v1__3__1.stl" scale="0.001 0.001 0.001"/>
    </geometry>
    <material name="silver"/>
  </visual>
  <collision>
    <origin xyz="-0.120998 0.062634 -0.118634" rpy="0 0 0"/>
    <geometry>
      <mesh filename="file://$(find bot_urdf_hii_description)/meshes/servo_small_clip_v1__3__1.stl" scale="0.001 0.001 0.001"/>
    </geometry>
  </collision>
</link>

<link name="Servo_RDS3115_v1__1__1">
  <inertial>
    <origin xyz="2.794533657118903e-07 -0.020000333315090657 -0.011078956540692853" rpy="0 0 0"/>
    <mass value="0.050997583494915726"/>
    <inertia ixx="1.5e-05" iyy="9e-06" izz="1e-05" ixy="-0.0" iyz="0.0" ixz="0.0"/>
  </inertial>
  <visual>
    <origin xyz="-0.120998 -0.131366 -0.101634" rpy="0 0 0"/>
    <geometry>
      <mesh filename="file://$(find bot_urdf_hii_description)/meshes/Servo_RDS3115_v1__1__1.stl" scale="0.001 0.001 0.001"/>
    </geometry>
    <material name="silver"/>
  </visual>
  <collision>
    <origin xyz="-0.120998 -0.131366 -0.101634" rpy="0 0 0"/>
    <geometry>
      <mesh filename="file://$(find bot_urdf_hii_description)/meshes/Servo_RDS3115_v1__1__1.stl" scale="0.001 0.001 0.001"/>
    </geometry>
  </collision>
</link>

<link name="Servo_RDS3115_v1__6__1">
  <inertial>
    <origin xyz="-7.632783294297951e-16 -0.020000333315091365 -0.011078956540693033" rpy="0 0 0"/>
    <mass value="0.050997583494915726"/>
    <inertia ixx="1.5e-05" iyy="9e-06" izz="1e-05" ixy="-0.0" iyz="0.0" ixz="0.0"/>
  </inertial>
  <visual>
    <origin xyz="0.122 -0.131366 -0.101634" rpy="0 0 0"/>
    <geometry>
      <mesh filename="file://$(find bot_urdf_hii_description)/meshes/Servo_RDS3115_v1__6__1.stl" scale="0.001 0.001 0.001"/>
    </geometry>
    <material name="silver"/>
  </visual>
  <collision>
    <origin xyz="0.122 -0.131366 -0.101634" rpy="0 0 0"/>
    <geometry>
      <mesh filename="file://$(find bot_urdf_hii_description)/meshes/Servo_RDS3115_v1__6__1.stl" scale="0.001 0.001 0.001"/>
    </geometry>
  </collision>
</link>

<link name="Servo_RDS3115_v1__7__1">
  <inertial>
    <origin xyz="-1.6653345369377348e-16 -0.02000033331509033 -0.0110789565406927" rpy="0 0 0"/>
    <mass value="0.050997583494915726"/>
    <inertia ixx="1.5e-05" iyy="9e-06" izz="1e-05" ixy="0.0" iyz="0.0" ixz="0.0"/>
  </inertial>
  <visual>
    <origin xyz="0.122 0.042634 -0.101634" rpy="0 0 0"/>
    <geometry>
      <mesh filename="file://$(find bot_urdf_hii_description)/meshes/Servo_RDS3115_v1__7__1.stl" scale="0.001 0.001 0.001"/>
    </geometry>
    <material name="silver"/>
  </visual>
  <collision>
    <origin xyz="0.122 0.042634 -0.101634" rpy="0 0 0"/>
    <geometry>
      <mesh filename="file://$(find bot_urdf_hii_description)/meshes/Servo_RDS3115_v1__7__1.stl" scale="0.001 0.001 0.001"/>
    </geometry>
  </collision>
</link>

<link name="Servo_RDS3115_v1_1">
  <inertial>
    <origin xyz="2.794533678490696e-07 0.019999666684909517 -0.011078956540692977" rpy="0 0 0"/>
    <mass value="0.050997583494915726"/>
    <inertia ixx="1.5e-05" iyy="9e-06" izz="1e-05" ixy="-0.0" iyz="0.0" ixz="0.0"/>
  </inertial>
  <visual>
    <origin xyz="-0.120998 0.082634 -0.101634" rpy="0 0 0"/>
    <geometry>
      <mesh filename="file://$(find bot_urdf_hii_description)/meshes/Servo_RDS3115_v1_1.stl" scale="0.001 0.001 0.001"/>
    </geometry>
    <material name="silver"/>
  </visual>
  <collision>
    <origin xyz="-0.120998 0.082634 -0.101634" rpy="0 0 0"/>
    <geometry>
      <mesh filename="file://$(find bot_urdf_hii_description)/meshes/Servo_RDS3115_v1_1.stl" scale="0.001 0.001 0.001"/>
    </geometry>
  </collision>
</link>

<link name="servo_big_clip_v1__7__1">
  <inertial>
    <origin xyz="1.0042926952558151e-07 -0.02550033331509069 -0.017673393166893855" rpy="0 0 0"/>
    <mass value="0.011882867210540276"/>
    <inertia ixx="7e-06" iyy="2e-06" izz="6e-06" ixy="0.0" iyz="-0.0" ixz="0.0"/>
  </inertial>
  <visual>
    <origin xyz="-0.120998 -0.136366 -0.081634" rpy="0 0 0"/>
    <geometry>
      <mesh filename="file://$(find bot_urdf_hii_description)/meshes/servo_big_clip_v1__7__1.stl" scale="0.001 0.001 0.001"/>
    </geometry>
    <material name="silver"/>
  </visual>
  <collision>
    <origin xyz="-0.120998 -0.136366 -0.081634" rpy="0 0 0"/>
    <geometry>
      <mesh filename="file://$(find bot_urdf_hii_description)/meshes/servo_big_clip_v1__7__1.stl" scale="0.001 0.001 0.001"/>
    </geometry>
  </collision>
</link>

<link name="servo_big_clip_v1_1">
  <inertial>
    <origin xyz="-1.790240984345104e-07 -0.02550033331509137 -0.017673393166893966" rpy="0 0 0"/>
    <mass value="0.011882867210540276"/>
    <inertia ixx="7e-06" iyy="2e-06" izz="6e-06" ixy="0.0" iyz="-0.0" ixz="0.0"/>
  </inertial>
  <visual>
    <origin xyz="0.122 -0.136366 -0.081634" rpy="0 0 0"/>
    <geometry>
      <mesh filename="file://$(find bot_urdf_hii_description)/meshes/servo_big_clip_v1_1.stl" scale="0.001 0.001 0.001"/>
    </geometry>
    <material name="silver"/>
  </visual>
  <collision>
    <origin xyz="0.122 -0.136366 -0.081634" rpy="0 0 0"/>
    <geometry>
      <mesh filename="file://$(find bot_urdf_hii_description)/meshes/servo_big_clip_v1_1.stl" scale="0.001 0.001 0.001"/>
    </geometry>
  </collision>
</link>

<link name="servo_big_clip_v1__2__1">
  <inertial>
    <origin xyz="-1.790240979626656e-07 0.025499666684909744 -0.017673393166893592" rpy="0 0 0"/>
    <mass value="0.011882867210540276"/>
    <inertia ixx="7e-06" iyy="2e-06" izz="6e-06" ixy="0.0" iyz="-0.0" ixz="0.0"/>
  </inertial>
  <visual>
    <origin xyz="0.122 0.087634 -0.081634" rpy="0 0 0"/>
    <geometry>
      <mesh filename="file://$(find bot_urdf_hii_description)/meshes/servo_big_clip_v1__2__1.stl" scale="0.001 0.001 0.001"/>
    </geometry>
    <material name="silver"/>
  </visual>
  <collision>
    <origin xyz="0.122 0.087634 -0.081634" rpy="0 0 0"/>
    <geometry>
      <mesh filename="file://$(find bot_urdf_hii_description)/meshes/servo_big_clip_v1__2__1.stl" scale="0.001 0.001 0.001"/>
    </geometry>
  </collision>
</link>

<link name="servo_big_clip_v1__1__1">
  <inertial>
    <origin xyz="1.0042926944231478e-07 0.025499666684909578 -0.017673393166893883" rpy="0 0 0"/>
    <mass value="0.011882867210540276"/>
    <inertia ixx="7e-06" iyy="2e-06" izz="6e-06" ixy="0.0" iyz="-0.0" ixz="0.0"/>
  </inertial>
  <visual>
    <origin xyz="-0.120998 0.087634 -0.081634" rpy="0 0 0"/>
    <geometry>
      <mesh filename="file://$(find bot_urdf_hii_description)/meshes/servo_big_clip_v1__1__1.stl" scale="0.001 0.001 0.001"/>
    </geometry>
    <material name="silver"/>
  </visual>
  <collision>
    <origin xyz="-0.120998 0.087634 -0.081634" rpy="0 0 0"/>
    <geometry>
      <mesh filename="file://$(find bot_urdf_hii_description)/meshes/servo_big_clip_v1__1__1.stl" scale="0.001 0.001 0.001"/>
    </geometry>
  </collision>
</link>

<link name="lag1_v9_1">
  <inertial>
    <origin xyz="2.487264359474217e-07 -7.55048806869163e-06 -0.04072502883613513" rpy="0 0 0"/>
    <mass value="0.03430898989942815"/>
    <inertia ixx="2.8e-05" iyy="2.6e-05" izz="4e-06" ixy="0.0" iyz="-0.0" ixz="0.0"/>
  </inertial>
  <visual>
    <origin xyz="-0.120998 -0.110866 -0.054634" rpy="0 0 0"/>
    <geometry>
      <mesh filename="file://$(find bot_urdf_hii_description)/meshes/lag1_v9_1.stl" scale="0.001 0.001 0.001"/>
    </geometry>
    <material name="silver"/>
  </visual>
  <collision>
    <origin xyz="-0.120998 -0.110866 -0.054634" rpy="0 0 0"/>
    <geometry>
      <mesh filename="file://$(find bot_urdf_hii_description)/meshes/lag1_v9_1.stl" scale="0.001 0.001 0.001"/>
    </geometry>
  </collision>
</link>

<link name="lag1_v9__1__1">
  <inertial>
    <origin xyz="-3.072693134653637e-08 -7.55048806944103e-06 -0.0407250288361353" rpy="0 0 0"/>
    <mass value="0.03430898989942815"/>
    <inertia ixx="2.8e-05" iyy="2.6e-05" izz="4e-06" ixy="0.0" iyz="-0.0" ixz="0.0"/>
  </inertial>
  <visual>
    <origin xyz="0.122 -0.110866 -0.054634" rpy="0 0 0"/>
    <geometry>
      <mesh filename="file://$(find bot_urdf_hii_description)/meshes/lag1_v9__1__1.stl" scale="0.001 0.001 0.001"/>
    </geometry>
    <material name="silver"/>
  </visual>
  <collision>
    <origin xyz="0.122 -0.110866 -0.054634" rpy="0 0 0"/>
    <geometry>
      <mesh filename="file://$(find bot_urdf_hii_description)/meshes/lag1_v9__1__1.stl" scale="0.001 0.001 0.001"/>
    </geometry>
  </collision>
</link>

<link name="lag1_v9__3__1">
  <inertial>
    <origin xyz="-3.072693151306982e-08 -7.550488068303052e-06 -0.04072502883613494" rpy="0 0 0"/>
    <mass value="0.03430898989942815"/>
    <inertia ixx="2.8e-05" iyy="2.6e-05" izz="4e-06" ixy="0.0" iyz="-0.0" ixz="0.0"/>
  </inertial>
  <visual>
    <origin xyz="0.122 0.062134 -0.054634" rpy="0 0 0"/>
    <geometry>
      <mesh filename="file://$(find bot_urdf_hii_description)/meshes/lag1_v9__3__1.stl" scale="0.001 0.001 0.001"/>
    </geometry>
    <material name="silver"/>
  </visual>
  <collision>
    <origin xyz="0.122 0.062134 -0.054634" rpy="0 0 0"/>
    <geometry>
      <mesh filename="file://$(find bot_urdf_hii_description)/meshes/lag1_v9__3__1.stl" scale="0.001 0.001 0.001"/>
    </geometry>
  </collision>
</link>

<link name="lag1_v9__2__1">
  <inertial>
    <origin xyz="2.48726435864155e-07 -7.550488068337746e-06 -0.04072502883613521" rpy="0 0 0"/>
    <mass value="0.03430898989942815"/>
    <inertia ixx="2.8e-05" iyy="2.6e-05" izz="4e-06" ixy="0.0" iyz="-0.0" ixz="0.0"/>
  </inertial>
  <visual>
    <origin xyz="-0.120998 0.062134 -0.054634" rpy="0 0 0"/>
    <geometry>
      <mesh filename="file://$(find bot_urdf_hii_description)/meshes/lag1_v9__2__1.stl" scale="0.001 0.001 0.001"/>
    </geometry>
    <material name="silver"/>
  </visual>
  <collision>
    <origin xyz="-0.120998 0.062134 -0.054634" rpy="0 0 0"/>
    <geometry>
      <mesh filename="file://$(find bot_urdf_hii_description)/meshes/lag1_v9__2__1.stl" scale="0.001 0.001 0.001"/>
    </geometry>
  </collision>
</link>

<link name="servo_small_clip_v1__9__1">
  <inertial>
    <origin xyz="2.4702462297909733e-14 -3.3331509028539097e-07 -0.006816401170189071" rpy="0 0 0"/>
    <mass value="0.009145592822398149"/>
    <inertia ixx="3e-06" iyy="1e-06" izz="3e-06" ixy="0.0" iyz="0.0" ixz="0.0"/>
  </inertial>
  <visual>
    <origin xyz="0.122 0.062134 0.025366" rpy="0 0 0"/>
    <geometry>
      <mesh filename="file://$(find bot_urdf_hii_description)/meshes/servo_small_clip_v1__9__1.stl" scale="0.001 0.001 0.001"/>
    </geometry>
    <material name="silver"/>
  </visual>
  <collision>
    <origin xyz="0.122 0.062134 0.025366" rpy="0 0 0"/>
    <geometry>
      <mesh filename="file://$(find bot_urdf_hii_description)/meshes/servo_small_clip_v1__9__1.stl" scale="0.001 0.001 0.001"/>
    </geometry>
  </collision>
</link>

<link name="servo_small_clip_v1__10__1">
  <inertial>
    <origin xyz="2.4896751327219135e-14 -3.3331509134704174e-07 -0.006816401170189404" rpy="0 0 0"/>
    <mass value="0.009145592822398149"/>
    <inertia ixx="3e-06" iyy="1e-06" izz="3e-06" ixy="0.0" iyz="0.0" ixz="0.0"/>
  </inertial>
  <visual>
    <origin xyz="0.122 -0.110866 0.025366" rpy="0 0 0"/>
    <geometry>
      <mesh filename="file://$(find bot_urdf_hii_description)/meshes/servo_small_clip_v1__10__1.stl" scale="0.001 0.001 0.001"/>
    </geometry>
    <material name="silver"/>
  </visual>
  <collision>
    <origin xyz="0.122 -0.110866 0.025366" rpy="0 0 0"/>
    <geometry>
      <mesh filename="file://$(find bot_urdf_hii_description)/meshes/servo_small_clip_v1__10__1.stl" scale="0.001 0.001 0.001"/>
    </geometry>
  </collision>
</link>

<link name="servo_small_clip_v1__11__1">
  <inertial>
    <origin xyz="2.794533921074427e-07 -3.333150904866189e-07 -0.006816401170189362" rpy="0 0 0"/>
    <mass value="0.009145592822398149"/>
    <inertia ixx="3e-06" iyy="1e-06" izz="3e-06" ixy="0.0" iyz="0.0" ixz="0.0"/>
  </inertial>
  <visual>
    <origin xyz="-0.120998 0.062134 0.025366" rpy="0 0 0"/>
    <geometry>
      <mesh filename="file://$(find bot_urdf_hii_description)/meshes/servo_small_clip_v1__11__1.stl" scale="0.001 0.001 0.001"/>
    </geometry>
    <material name="silver"/>
  </visual>
  <collision>
    <origin xyz="-0.120998 0.062134 0.025366" rpy="0 0 0"/>
    <geometry>
      <mesh filename="file://$(find bot_urdf_hii_description)/meshes/servo_small_clip_v1__11__1.stl" scale="0.001 0.001 0.001"/>
    </geometry>
  </collision>
</link>

<link name="servo_small_clip_v1__8__1">
  <inertial>
    <origin xyz="2.794533921907094e-07 -3.333150906809079e-07 -0.006816401170189258" rpy="0 0 0"/>
    <mass value="0.009145592822398149"/>
    <inertia ixx="3e-06" iyy="1e-06" izz="3e-06" ixy="0.0" iyz="0.0" ixz="0.0"/>
  </inertial>
  <visual>
    <origin xyz="-0.120998 -0.110866 0.025366" rpy="0 0 0"/>
    <geometry>
      <mesh filename="file://$(find bot_urdf_hii_description)/meshes/servo_small_clip_v1__8__1.stl" scale="0.001 0.001 0.001"/>
    </geometry>
    <material name="silver"/>
  </visual>
  <collision>
    <origin xyz="-0.120998 -0.110866 0.025366" rpy="0 0 0"/>
    <geometry>
      <mesh filename="file://$(find bot_urdf_hii_description)/meshes/servo_small_clip_v1__8__1.stl" scale="0.001 0.001 0.001"/>
    </geometry>
  </collision>
</link>

<link name="Servo_RDS3115_v1__11__1">
  <inertial>
    <origin xyz="0.011079289855784075 0.019999666684908643 3.333150903617188e-07" rpy="0 0 0"/>
    <mass value="0.050997583494915726"/>
    <inertia ixx="1e-05" iyy="9e-06" izz="1.5e-05" ixy="0.0" iyz="0.0" ixz="0.0"/>
  </inertial>
  <visual>
    <origin xyz="0.122 -0.090866 0.042366" rpy="0 0 0"/>
    <geometry>
      <mesh filename="file://$(find bot_urdf_hii_description)/meshes/Servo_RDS3115_v1__11__1.stl" scale="0.001 0.001 0.001"/>
    </geometry>
    <material name="silver"/>
  </visual>
  <collision>
    <origin xyz="0.122 -0.090866 0.042366" rpy="0 0 0"/>
    <geometry>
      <mesh filename="file://$(find bot_urdf_hii_description)/meshes/Servo_RDS3115_v1__11__1.stl" scale="0.001 0.001 0.001"/>
    </geometry>
  </collision>
</link>

<link name="Servo_RDS3115_v1__10__1">
  <inertial>
    <origin xyz="0.011079289855782853 0.01999966668490974 3.333150906809079e-07" rpy="0 0 0"/>
    <mass value="0.050997583494915726"/>
    <inertia ixx="1e-05" iyy="9e-06" izz="1.5e-05" ixy="0.0" iyz="0.0" ixz="0.0"/>
  </inertial>
  <visual>
    <origin xyz="0.122 0.082134 0.042366" rpy="0 0 0"/>
    <geometry>
      <mesh filename="file://$(find bot_urdf_hii_description)/meshes/Servo_RDS3115_v1__10__1.stl" scale="0.001 0.001 0.001"/>
    </geometry>
    <material name="silver"/>
  </visual>
  <collision>
    <origin xyz="0.122 0.082134 0.042366" rpy="0 0 0"/>
    <geometry>
      <mesh filename="file://$(find bot_urdf_hii_description)/meshes/Servo_RDS3115_v1__10__1.stl" scale="0.001 0.001 0.001"/>
    </geometry>
  </collision>
</link>

<link name="Servo_RDS3115_v1__9__1">
  <inertial>
    <origin xyz="0.011079569309150689 0.019999666684909538 3.3331509041722995e-07" rpy="0 0 0"/>
    <mass value="0.050997583494915726"/>
    <inertia ixx="1e-05" iyy="9e-06" izz="1.5e-05" ixy="0.0" iyz="0.0" ixz="0.0"/>
  </inertial>
  <visual>
    <origin xyz="-0.120998 0.082134 0.042366" rpy="0 0 0"/>
    <geometry>
      <mesh filename="file://$(find bot_urdf_hii_description)/meshes/Servo_RDS3115_v1__9__1.stl" scale="0.001 0.001 0.001"/>
    </geometry>
    <material name="silver"/>
  </visual>
  <collision>
    <origin xyz="-0.120998 0.082134 0.042366" rpy="0 0 0"/>
    <geometry>
      <mesh filename="file://$(find bot_urdf_hii_description)/meshes/Servo_RDS3115_v1__9__1.stl" scale="0.001 0.001 0.001"/>
    </geometry>
  </collision>
</link>

<link name="Servo_RDS3115_v1__8__1">
  <inertial>
    <origin xyz="0.011079569309150689 0.019999666684909323 3.3331509051437447e-07" rpy="0 0 0"/>
    <mass value="0.050997583494915726"/>
    <inertia ixx="1e-05" iyy="9e-06" izz="1.5e-05" ixy="-0.0" iyz="0.0" ixz="0.0"/>
  </inertial>
  <visual>
    <origin xyz="-0.120998 -0.090866 0.042366" rpy="0 0 0"/>
    <geometry>
      <mesh filename="file://$(find bot_urdf_hii_description)/meshes/Servo_RDS3115_v1__8__1.stl" scale="0.001 0.001 0.001"/>
    </geometry>
    <material name="silver"/>
  </visual>
  <collision>
    <origin xyz="-0.120998 -0.090866 0.042366" rpy="0 0 0"/>
    <geometry>
      <mesh filename="file://$(find bot_urdf_hii_description)/meshes/Servo_RDS3115_v1__8__1.stl" scale="0.001 0.001 0.001"/>
    </geometry>
  </collision>
</link>

<link name="servo_big_clip_v1__11__1">
  <inertial>
    <origin xyz="0.017673726481985105 0.025499666684909147 5.123391881856065e-07" rpy="0 0 0"/>
    <mass value="0.011882867210540276"/>
    <inertia ixx="6e-06" iyy="2e-06" izz="7e-06" ixy="0.0" iyz="0.0" ixz="0.0"/>
  </inertial>
  <visual>
    <origin xyz="0.102 -0.085866 0.042366" rpy="0 0 0"/>
    <geometry>
      <mesh filename="file://$(find bot_urdf_hii_description)/meshes/servo_big_clip_v1__11__1.stl" scale="0.001 0.001 0.001"/>
    </geometry>
    <material name="silver"/>
  </visual>
  <collision>
    <origin xyz="0.102 -0.085866 0.042366" rpy="0 0 0"/>
    <geometry>
      <mesh filename="file://$(find bot_urdf_hii_description)/meshes/servo_big_clip_v1__11__1.stl" scale="0.001 0.001 0.001"/>
    </geometry>
  </collision>
</link>

<link name="servo_big_clip_v1__10__1">
  <inertial>
    <origin xyz="0.017673726481984092 0.02549966668490984 5.123391885117345e-07" rpy="0 0 0"/>
    <mass value="0.011882867210540276"/>
    <inertia ixx="6e-06" iyy="2e-06" izz="7e-06" ixy="0.0" iyz="0.0" ixz="0.0"/>
  </inertial>
  <visual>
    <origin xyz="0.102 0.087134 0.042366" rpy="0 0 0"/>
    <geometry>
      <mesh filename="file://$(find bot_urdf_hii_description)/meshes/servo_big_clip_v1__10__1.stl" scale="0.001 0.001 0.001"/>
    </geometry>
    <material name="silver"/>
  </visual>
  <collision>
    <origin xyz="0.102 0.087134 0.042366" rpy="0 0 0"/>
    <geometry>
      <mesh filename="file://$(find bot_urdf_hii_description)/meshes/servo_big_clip_v1__10__1.stl" scale="0.001 0.001 0.001"/>
    </geometry>
  </collision>
</link>

<link name="servo_big_clip_v1__9__1">
  <inertial>
    <origin xyz="0.01767400593535201 0.025499666684909397 5.123391882411177e-07" rpy="0 0 0"/>
    <mass value="0.011882867210540276"/>
    <inertia ixx="6e-06" iyy="2e-06" izz="7e-06" ixy="-0.0" iyz="0.0" ixz="0.0"/>
  </inertial>
  <visual>
    <origin xyz="-0.140998 0.087134 0.042366" rpy="0 0 0"/>
    <geometry>
      <mesh filename="file://$(find bot_urdf_hii_description)/meshes/servo_big_clip_v1__9__1.stl" scale="0.001 0.001 0.001"/>
    </geometry>
    <material name="silver"/>
  </visual>
  <collision>
    <origin xyz="-0.140998 0.087134 0.042366" rpy="0 0 0"/>
    <geometry>
      <mesh filename="file://$(find bot_urdf_hii_description)/meshes/servo_big_clip_v1__9__1.stl" scale="0.001 0.001 0.001"/>
    </geometry>
  </collision>
</link>

<link name="servo_big_clip_v1__8__1">
  <inertial>
    <origin xyz="0.01767400593535101 0.025499666684909703 5.123391883452011e-07" rpy="0 0 0"/>
    <mass value="0.011882867210540276"/>
    <inertia ixx="6e-06" iyy="2e-06" izz="7e-06" ixy="0.0" iyz="0.0" ixz="0.0"/>
  </inertial>
  <visual>
    <origin xyz="-0.140998 -0.085866 0.042366" rpy="0 0 0"/>
    <geometry>
      <mesh filename="file://$(find bot_urdf_hii_description)/meshes/servo_big_clip_v1__8__1.stl" scale="0.001 0.001 0.001"/>
    </geometry>
    <material name="silver"/>
  </visual>
  <collision>
    <origin xyz="-0.140998 -0.085866 0.042366" rpy="0 0 0"/>
    <geometry>
      <mesh filename="file://$(find bot_urdf_hii_description)/meshes/servo_big_clip_v1__8__1.stl" scale="0.001 0.001 0.001"/>
    </geometry>
  </collision>
</link>

<link name="lag_2_v7__1__1">
  <inertial>
    <origin xyz="0.04914040820366403 5.623370695803653e-06 6.446678870453137e-07" rpy="0 0 0"/>
    <mass value="0.039693577545623984"/>
    <inertia ixx="4e-06" iyy="4.8e-05" izz="4.8e-05" ixy="-0.0" iyz="-0.0" ixz="0.0"/>
  </inertial>
  <visual>
    <origin xyz="0.075 -0.111366 0.042366" rpy="0 0 0"/>
    <geometry>
      <mesh filename="file://$(find bot_urdf_hii_description)/meshes/lag_2_v7__1__1.stl" scale="0.001 0.001 0.001"/>
    </geometry>
    <material name="silver"/>
  </visual>
  <collision>
    <origin xyz="0.075 -0.111366 0.042366" rpy="0 0 0"/>
    <geometry>
      <mesh filename="file://$(find bot_urdf_hii_description)/meshes/lag_2_v7__1__1.stl" scale="0.001 0.001 0.001"/>
    </geometry>
  </collision>
</link>

<link name="lag_2_v7__3__1">
  <inertial>
    <origin xyz="0.04914040820366368 5.62337069576202e-06 6.446678873645029e-07" rpy="0 0 0"/>
    <mass value="0.039693577545623984"/>
    <inertia ixx="4e-06" iyy="4.8e-05" izz="4.8e-05" ixy="-0.0" iyz="-0.0" ixz="0.0"/>
  </inertial>
  <visual>
    <origin xyz="0.075 0.061634 0.042366" rpy="0 0 0"/>
    <geometry>
      <mesh filename="file://$(find bot_urdf_hii_description)/meshes/lag_2_v7__3__1.stl" scale="0.001 0.001 0.001"/>
    </geometry>
    <material name="silver"/>
  </visual>
  <collision>
    <origin xyz="0.075 0.061634 0.042366" rpy="0 0 0"/>
    <geometry>
      <mesh filename="file://$(find bot_urdf_hii_description)/meshes/lag_2_v7__3__1.stl" scale="0.001 0.001 0.001"/>
    </geometry>
  </collision>
</link>

<link name="lag_2_v7_1">
  <inertial>
    <origin xyz="0.04914068765703142 5.6233706953318086e-06 6.446678872049083e-07" rpy="0 0 0"/>
    <mass value="0.039693577545623984"/>
    <inertia ixx="4e-06" iyy="4.8e-05" izz="4.8e-05" ixy="-0.0" iyz="-0.0" ixz="0.0"/>
  </inertial>
  <visual>
    <origin xyz="-0.167998 -0.111366 0.042366" rpy="0 0 0"/>
    <geometry>
      <mesh filename="file://$(find bot_urdf_hii_description)/meshes/lag_2_v7_1.stl" scale="0.001 0.001 0.001"/>
    </geometry>
    <material name="silver"/>
  </visual>
  <collision>
    <origin xyz="-0.167998 -0.111366 0.042366" rpy="0 0 0"/>
    <geometry>
      <mesh filename="file://$(find bot_urdf_hii_description)/meshes/lag_2_v7_1.stl" scale="0.001 0.001 0.001"/>
    </geometry>
  </collision>
</link>

<link name="lag_2_v7__2__1">
  <inertial>
    <origin xyz="0.04914068765703136 5.6233706955954865e-06 6.446678870800082e-07" rpy="0 0 0"/>
    <mass value="0.039693577545623984"/>
    <inertia ixx="4e-06" iyy="4.8e-05" izz="4.8e-05" ixy="-0.0" iyz="-0.0" ixz="0.0"/>
  </inertial>
  <visual>
    <origin xyz="-0.167998 0.061634 0.042366" rpy="0 0 0"/>
    <geometry>
      <mesh filename="file://$(find bot_urdf_hii_description)/meshes/lag_2_v7__2__1.stl" scale="0.001 0.001 0.001"/>
    </geometry>
    <material name="silver"/>
  </visual>
  <collision>
    <origin xyz="-0.167998 0.061634 0.042366" rpy="0 0 0"/>
    <geometry>
      <mesh filename="file://$(find bot_urdf_hii_description)/meshes/lag_2_v7__2__1.stl" scale="0.001 0.001 0.001"/>
    </geometry>
  </collision>
</link>

<joint name="Rigid 1" type="fixed">
  <origin xyz="0.121498 0.074366 0.145634" rpy="0 0 0"/>
  <parent link="base_link"/>
  <child link="servo_small_clip_v1__6__1"/>
</joint>

<joint name="Rigid 2" type="fixed">
  <origin xyz="0.121498 -0.025634 0.145634" rpy="0 0 0"/>
  <parent link="base_link"/>
  <child link="servo_small_clip_v1__5__1"/>
</joint>

<joint name="Rigid 3" type="fixed">
  <origin xyz="-0.1215 0.074366 0.145634" rpy="0 0 0"/>
  <parent link="base_link"/>
  <child link="servo_small_clip_v1__7__1"/>
</joint>

<joint name="Rigid 4" type="fixed">
  <origin xyz="-0.1215 -0.025634 0.145634" rpy="0 0 0"/>
  <parent link="base_link"/>
  <child link="servo_small_clip_v1__4__1"/>
</joint>

<joint name="Rigid 5" type="fixed">
  <origin xyz="-0.02 -0.017 0.0" rpy="0 0 0"/>
  <parent link="servo_small_clip_v1__4__1"/>
  <child link="Servo_RDS3115_v1__5__1"/>
</joint>

<joint name="Rigid 6" type="fixed">
  <origin xyz="0.02 -0.017 0.0" rpy="0 0 0"/>
  <parent link="servo_small_clip_v1__5__1"/>
  <child link="Servo_RDS3115_v1__4__1"/>
</joint>

<joint name="Rigid 7" type="fixed">
  <origin xyz="-0.02 0.017 0.0" rpy="0 0 0"/>
  <parent link="servo_small_clip_v1__7__1"/>
  <child link="Servo_RDS3115_v1__3__1"/>
</joint>

<joint name="Rigid 8" type="fixed">
  <origin xyz="0.02 0.017 0.0" rpy="0 0 0"/>
  <parent link="servo_small_clip_v1__6__1"/>
  <child link="Servo_RDS3115_v1__2__1"/>
</joint>

<joint name="Revolute 9" type="continuous">
  <origin xyz="0.005 0.02 0.0" rpy="0 0 0"/>
  <parent link="Servo_RDS3115_v1__2__1"/>
  <child link="servo_big_clip_v1__4__1"/>
  <axis xyz="1.0 0.0 -0.0"/>
</joint>

<joint name="Revolute 10" type="continuous">
  <origin xyz="0.045 0.02 0.0" rpy="0 0 0"/>
  <parent link="Servo_RDS3115_v1__3__1"/>
  <child link="servo_big_clip_v1__6__1"/>
  <axis xyz="1.0 -0.0 -0.0"/>
</joint>

<joint name="Revolute 11" type="continuous">
  <origin xyz="0.005 -0.02 0.0" rpy="0 0 0"/>
  <parent link="Servo_RDS3115_v1__4__1"/>
  <child link="servo_big_clip_v1__5__1"/>
  <axis xyz="1.0 -0.0 -0.0"/>
</joint>

<joint name="Revolute 12" type="continuous">
  <origin xyz="0.045 -0.02 0.0" rpy="0 0 0"/>
  <parent link="Servo_RDS3115_v1__5__1"/>
  <child link="servo_big_clip_v1__3__1"/>
  <axis xyz="1.0 -0.0 -0.0"/>
</joint>

<joint name="Rigid 13" type="fixed">
  <origin xyz="-0.0255 0.0 -0.027" rpy="0 0 0"/>
  <parent link="servo_big_clip_v1__4__1"/>
  <child link="servo_small_clip_v1__2__1"/>
</joint>

<joint name="Rigid 14" type="fixed">
  <origin xyz="-0.0255 0.0 -0.027" rpy="0 0 0"/>
  <parent link="servo_big_clip_v1__6__1"/>
  <child link="servo_small_clip_v1__1__1"/>
</joint>

<joint name="Rigid 15" type="fixed">
  <origin xyz="-0.0255 0.0 -0.027" rpy="0 0 0"/>
  <parent link="servo_big_clip_v1__3__1"/>
  <child link="servo_small_clip_v1_1"/>
</joint>

<joint name="Rigid 16" type="fixed">
  <origin xyz="-0.0255 0.0 -0.027" rpy="0 0 0"/>
  <parent link="servo_big_clip_v1__5__1"/>
  <child link="servo_small_clip_v1__3__1"/>
</joint>

<joint name="Rigid 17" type="fixed">
  <origin xyz="0.0 0.02 -0.017" rpy="0 0 0"/>
  <parent link="servo_small_clip_v1__2__1"/>
  <child link="Servo_RDS3115_v1__1__1"/>
</joint>

<joint name="Rigid 18" type="fixed">
  <origin xyz="0.0 0.02 -0.017" rpy="0 0 0"/>
  <parent link="servo_small_clip_v1__1__1"/>
  <child link="Servo_RDS3115_v1__6__1"/>
</joint>

<joint name="Rigid 19" type="fixed">
  <origin xyz="0.0 0.02 -0.017" rpy="0 0 0"/>
  <parent link="servo_small_clip_v1_1"/>
  <child link="Servo_RDS3115_v1__7__1"/>
</joint>

<joint name="Rigid 20" type="fixed">
  <origin xyz="0.0 -0.02 -0.017" rpy="0 0 0"/>
  <parent link="servo_small_clip_v1__3__1"/>
  <child link="Servo_RDS3115_v1_1"/>
</joint>

<joint name="Revolute 21" type="continuous">
  <origin xyz="0.0 0.005 -0.02" rpy="0 0 0"/>
  <parent link="Servo_RDS3115_v1__1__1"/>
  <child link="servo_big_clip_v1__7__1"/>
  <axis xyz="-0.0 -1.0 0.0"/>
</joint>

<joint name="Revolute 22" type="continuous">
  <origin xyz="0.0 0.005 -0.02" rpy="0 0 0"/>
  <parent link="Servo_RDS3115_v1__6__1"/>
  <child link="servo_big_clip_v1_1"/>
  <axis xyz="-0.0 -1.0 0.0"/>
</joint>

<joint name="Revolute 23" type="continuous">
  <origin xyz="0.0 -0.045 -0.02" rpy="0 0 0"/>
  <parent link="Servo_RDS3115_v1__7__1"/>
  <child link="servo_big_clip_v1__2__1"/>
  <axis xyz="-0.0 -1.0 0.0"/>
</joint>

<joint name="Revolute 24" type="continuous">
  <origin xyz="0.0 -0.005 -0.02" rpy="0 0 0"/>
  <parent link="Servo_RDS3115_v1_1"/>
  <child link="servo_big_clip_v1__1__1"/>
  <axis xyz="-0.0 -1.0 0.0"/>
</joint>

<joint name="Rigid 25" type="fixed">
  <origin xyz="0.0 -0.0255 -0.027" rpy="0 0 0"/>
  <parent link="servo_big_clip_v1__7__1"/>
  <child link="lag1_v9_1"/>
</joint>

<joint name="Rigid 26" type="fixed">
  <origin xyz="0.0 -0.0255 -0.027" rpy="0 0 0"/>
  <parent link="servo_big_clip_v1_1"/>
  <child link="lag1_v9__1__1"/>
</joint>

<joint name="Rigid 27" type="fixed">
  <origin xyz="0.0 0.0255 -0.027" rpy="0 0 0"/>
  <parent link="servo_big_clip_v1__2__1"/>
  <child link="lag1_v9__3__1"/>
</joint>

<joint name="Rigid 28" type="fixed">
  <origin xyz="0.0 0.0255 -0.027" rpy="0 0 0"/>
  <parent link="servo_big_clip_v1__1__1"/>
  <child link="lag1_v9__2__1"/>
</joint>

<joint name="Rigid 29" type="fixed">
  <origin xyz="0.0 0.0 -0.08" rpy="0 0 0"/>
  <parent link="lag1_v9__3__1"/>
  <child link="servo_small_clip_v1__9__1"/>
</joint>

<joint name="Rigid 30" type="fixed">
  <origin xyz="0.0 0.0 -0.08" rpy="0 0 0"/>
  <parent link="lag1_v9__1__1"/>
  <child link="servo_small_clip_v1__10__1"/>
</joint>

<joint name="Rigid 31" type="fixed">
  <origin xyz="0.0 0.0 -0.08" rpy="0 0 0"/>
  <parent link="lag1_v9__2__1"/>
  <child link="servo_small_clip_v1__11__1"/>
</joint>

<joint name="Rigid 32" type="fixed">
  <origin xyz="0.0 0.0 -0.08" rpy="0 0 0"/>
  <parent link="lag1_v9_1"/>
  <child link="servo_small_clip_v1__8__1"/>
</joint>

<joint name="Rigid 33" type="fixed">
  <origin xyz="0.0 -0.02 -0.017" rpy="0 0 0"/>
  <parent link="servo_small_clip_v1__10__1"/>
  <child link="Servo_RDS3115_v1__11__1"/>
</joint>

<joint name="Rigid 34" type="fixed">
  <origin xyz="0.0 -0.02 -0.017" rpy="0 0 0"/>
  <parent link="servo_small_clip_v1__9__1"/>
  <child link="Servo_RDS3115_v1__10__1"/>
</joint>

<joint name="Rigid 35" type="fixed">
  <origin xyz="0.0 -0.02 -0.017" rpy="0 0 0"/>
  <parent link="servo_small_clip_v1__11__1"/>
  <child link="Servo_RDS3115_v1__9__1"/>
</joint>

<joint name="Rigid 36" type="fixed">
  <origin xyz="0.0 -0.02 -0.017" rpy="0 0 0"/>
  <parent link="servo_small_clip_v1__8__1"/>
  <child link="Servo_RDS3115_v1__8__1"/>
</joint>

<joint name="Revolute 37" type="continuous">
  <origin xyz="0.02 -0.005 0.0" rpy="0 0 0"/>
  <parent link="Servo_RDS3115_v1__11__1"/>
  <child link="servo_big_clip_v1__11__1"/>
  <axis xyz="-0.0 1.0 -0.0"/>
</joint>

<joint name="Revolute 38" type="continuous">
  <origin xyz="0.02 -0.005 0.0" rpy="0 0 0"/>
  <parent link="Servo_RDS3115_v1__10__1"/>
  <child link="servo_big_clip_v1__10__1"/>
  <axis xyz="-0.0 1.0 -0.0"/>
</joint>

<joint name="Revolute 39" type="continuous">
  <origin xyz="0.02 -0.005 0.0" rpy="0 0 0"/>
  <parent link="Servo_RDS3115_v1__9__1"/>
  <child link="servo_big_clip_v1__9__1"/>
  <axis xyz="-0.0 1.0 -0.0"/>
</joint>

<joint name="Revolute 40" type="continuous">
  <origin xyz="0.02 -0.005 0.0" rpy="0 0 0"/>
  <parent link="Servo_RDS3115_v1__8__1"/>
  <child link="servo_big_clip_v1__8__1"/>
  <axis xyz="-0.0 -1.0 0.0"/>
</joint>

<joint name="Rigid 41" type="fixed">
  <origin xyz="0.027 0.0255 0.0" rpy="0 0 0"/>
  <parent link="servo_big_clip_v1__11__1"/>
  <child link="lag_2_v7__1__1"/>
</joint>

<joint name="Rigid 42" type="fixed">
  <origin xyz="0.027 0.0255 0.0" rpy="0 0 0"/>
  <parent link="servo_big_clip_v1__10__1"/>
  <child link="lag_2_v7__3__1"/>
</joint>

<joint name="Rigid 43" type="fixed">
  <origin xyz="0.027 0.0255 0.0" rpy="0 0 0"/>
  <parent link="servo_big_clip_v1__8__1"/>
  <child link="lag_2_v7_1"/>
</joint>

<joint name="Rigid 44" type="fixed">
  <origin xyz="0.027 0.0255 0.0" rpy="0 0 0"/>
  <parent link="servo_big_clip_v1__9__1"/>
  <child link="lag_2_v7__2__1"/>
</joint>

</robot>
